<?xml version= "1.0"?>
<robot name="ball_balancer" xmlns:xacro="http://ros.org/wiki/xacro">
 

 <gazebo>
  <plugin name="gazebo_ros_control" filename="libgazebo_ros_control.so">
   <robotNamespace>/ball_balancer</robotNamespace>
  </plugin>
 </gazebo>

<!-- Base Link -->

 <link name="base_link">
  <visual>
   <geometry>
     <mesh filename="package://ball_balancer/meshes/Base_Link.dae"/>
   </geometry>
   <origin xyz="0 0 0" rpy="0 0 0"/>
  </visual>

  <collision>
   <geometry>
     <mesh filename="package://ball_balancer/meshes/Base_Link.dae"/>
   </geometry>
   <origin xyz="0 0 0" rpy="0 0 0"/>
  </collision>

  <inertial>
    <mass value="10"/>
    <inertia ixx="1" ixy="0.0" ixz="0.0" iyy="1" iyz="0.0" izz="1"/> 
    <origin xyz="0 0 0" rpy="0 0 0"/> 
  </inertial>
 </link>

<!-- SeeSaw -->
 <link name="seesaw">
  <visual>
   <geometry>
     <mesh filename="package://ball_balancer/meshes/SeeSaw.dae"/>
   </geometry>
   <origin xyz="-.015 0 -0.01" rpy="0 0 ${radians(90)}"/>
  </visual>
  
  <collision>
   <geometry>
     <mesh filename="package://ball_balancer/meshes/SeeSaw.dae"/>
   </geometry>
   <origin xyz="-.015 0 -0.01" rpy="0 0 ${radians(90)}"/>
  </collision> 

  <inertial>
    <mass value="1"/>
    <inertia ixx="1" ixy="0.0" ixz="0.0" iyy="1" iyz="0.0" izz="1"/>
    <origin xyz="0 0 0" rpy="0 0 0"/>
  </inertial>
 </link>
       
<!-- Seesaw Joint -->
 <joint name="seesaw_joint" type="revolute">
  <parent link="base_link"/>
  <child link="seesaw"/>
  <limit lower="${radians(-90)}" upper="${radians(90)}" effort="2" velocity="5"/>
  <axis xyz="1 0 0" rpy="0 0 0"/>
  <origin xyz=".015 0 0.02621" rpy="0 0 0"/>
 </joint>

<!-- Joint to Actuator Transmission -->
 <transmission name="simple_trans">
  <type>transmission_interface/SimpleTransmission</type>
  <joint name="seesaw_joint">
   <hardwareInterface>hardware_interface/EffortJointInterface</hardwareInterface>
  </joint>
  <actuator name="motor1">
   <hardwareInterface>hardware_interface/EffortJointInterface</hardwareInterface>
   <mechanicalReduction>1</mechanicalReduction>
  </actuator>
 </transmission>

<!-- Ultrasonic sensor -->
 <link name="ultrasonic_sensor">
  <visual>
   <geometry>
    <box size=".005 .00125 .005"/>
   </geometry>
  </visual> 
  
  <collision> 
   <geometry>
    <box size=".005 .00125 .005"/>
   </geometry>
  </collision>
 </link>

<!-- Ultrasonic Joint -->  
 <joint name="ultrasonic_joint" type="fixed">
  <parent link="seesaw"/>
  <child link="ultrasonic_sensor"/>
  <origin xyz="-0.015 .0775 .0075" rpy="0 0 0"/>
 </joint>  

<!-- Ultrasonic sensor definition -->
<gazebo reference="ultrasonic_sensor">
 <sensor type="ray" name="sonar">
  <pose>0 0 0 0 0 -${radians(90)}</pose>
  <visualize>true</visualize>
  <update_rate>5</update_rate>
  <ray>
    <scan>
     <horizontal>
      <samples>5</samples>
      <resolution>.5</resolution>
      <min_angle>-0.20</min_angle>
      <max_angle>0.20</max_angle>
     </horizontal>
    </scan>
    <range>
     <min>0.001</min>    <!-- Looks like minimum range for Ultrasonic sensor is 1mm -->
     <max>0.75</max>
     <resolution>0.0001</resolution>
    </range>
   </ray>
   <plugin filename="libgazebo_ros_range.so" name="gazebo_ros_range">
    <gaussianNoise>0</gaussianNoise>
    <alwaysOn>true</alwaysOn>
    <updateRate>5</updateRate>
    <topicName>sonar</topicName>
    <frameName>ultrasonic_sensor</frameName>
    <fov>0.5</fov>
    <radiation>ultrasound</radiation>
   </plugin>
 </sensor>    
</gazebo>
 
</robot>

